[2021-03-29 20:57:23] ERROR local variable 'role_id' referenced before assignment
[2021-03-29 20:57:23] ERROR Error in Getting User Credentials
Traceback (most recent call last):
  File "G:\Adventbiz\FinanceControlledApplication\BusinessModules\ModuleDetails\views.py", line 66, in get_user_credentials
    user_role = UserRole.objects.filter(role_id = role_id)
UnboundLocalError: local variable 'role_id' referenced before assignment
[2021-03-31 00:39:45] ERROR local variable 'user_id' referenced before assignment
[2021-03-31 00:39:45] ERROR Error in Getting User Credentials
Traceback (most recent call last):
  File "G:\Adventbiz\FinanceControlledApplication\BusinessModules\ModuleDetails\views.py", line 61, in get_user_credentials
    users = Users.objects.filter(id = user_id, is_active = 1)
UnboundLocalError: local variable 'user_id' referenced before assignment
[2021-03-31 03:19:57] ERROR local variable 'user_name' referenced before assignment
[2021-03-31 03:19:57] ERROR Error in Login User
Traceback (most recent call last):
  File "G:\Adventbiz\FinanceControlledApplication\BusinessModules\ModuleDetails\views.py", line 31, in get_user_login
    user = authenticate(request, username = user_name, password = password)
UnboundLocalError: local variable 'user_name' referenced before assignment
[2021-03-31 03:38:03] ERROR local variable 'user_name' referenced before assignment
[2021-03-31 03:38:03] ERROR Error in Login User
Traceback (most recent call last):
  File "G:\Adventbiz\FinanceControlledApplication\BusinessModules\ModuleDetails\views.py", line 31, in get_user_login
    user = authenticate(request, username = user_name, password = password)
UnboundLocalError: local variable 'user_name' referenced before assignment
[2021-05-06 12:35:52] ERROR list index out of range
[2021-05-06 12:35:52] ERROR Error in Getting User Credentials
Traceback (most recent call last):
  File "D:\Adventbiz\FinanceControlledApplication\BusinessModules\ModuleDetails\views.py", line 101, in get_user_credentials
    tenants_id_unique = list(set(tenants_ids))[0]
IndexError: list index out of range
[2021-05-06 12:47:31] ERROR list index out of range
[2021-05-06 12:47:31] ERROR Error in Getting User Credentials
Traceback (most recent call last):
  File "D:\Adventbiz\FinanceControlledApplication\BusinessModules\ModuleDetails\views.py", line 101, in get_user_credentials
    tenants_id_unique = list(set(tenants_ids))[0]
IndexError: list index out of range
[2021-05-06 12:48:02] ERROR Expecting value: line 3 column 1 (char 20)
[2021-05-06 12:48:02] ERROR Error in Getting User Credentials
Traceback (most recent call last):
  File "D:\Adventbiz\FinanceControlledApplication\BusinessModules\ModuleDetails\views.py", line 70, in get_user_credentials
    data = json.loads(body)
  File "c:\users\user\appdata\local\programs\python\python39\lib\json\__init__.py", line 346, in loads
    return _default_decoder.decode(s)
  File "c:\users\user\appdata\local\programs\python\python39\lib\json\decoder.py", line 337, in decode
    obj, end = self.raw_decode(s, idx=_w(s, 0).end())
  File "c:\users\user\appdata\local\programs\python\python39\lib\json\decoder.py", line 355, in raw_decode
    raise JSONDecodeError("Expecting value", s, err.value) from None
json.decoder.JSONDecodeError: Expecting value: line 3 column 1 (char 20)
[2021-05-06 12:48:07] ERROR Expecting value: line 3 column 1 (char 20)
[2021-05-06 12:48:07] ERROR Error in Getting User Credentials
Traceback (most recent call last):
  File "D:\Adventbiz\FinanceControlledApplication\BusinessModules\ModuleDetails\views.py", line 70, in get_user_credentials
    data = json.loads(body)
  File "c:\users\user\appdata\local\programs\python\python39\lib\json\__init__.py", line 346, in loads
    return _default_decoder.decode(s)
  File "c:\users\user\appdata\local\programs\python\python39\lib\json\decoder.py", line 337, in decode
    obj, end = self.raw_decode(s, idx=_w(s, 0).end())
  File "c:\users\user\appdata\local\programs\python\python39\lib\json\decoder.py", line 355, in raw_decode
    raise JSONDecodeError("Expecting value", s, err.value) from None
json.decoder.JSONDecodeError: Expecting value: line 3 column 1 (char 20)
[2021-05-31 09:10:28] INFO Executing SQL Query..
[2021-05-31 09:10:28] INFO SELECT user_name, mail_id, department, reporting_manager, user_id FROM business_modules.new_users;
[2021-05-31 09:10:28] INFO Executing SQL Query..
[2021-05-31 09:10:28] INFO SELECT user_name, mail_id, department, reporting_manager, user_id FROM business_modules.new_users WHERE is_active = 1;
[2021-05-31 09:11:14] INFO Executing SQL Query..
[2021-05-31 09:11:14] INFO SELECT user_name, mail_id, department, reporting_manager, user_id FROM business_modules.new_users;
[2021-05-31 09:11:15] INFO Executing SQL Query..
[2021-05-31 09:11:15] INFO SELECT user_name, mail_id, department, reporting_manager, user_id FROM business_modules.new_users WHERE is_active = 1;
[2021-05-31 10:30:00] ERROR Cannot resolve keyword 'user_name' into field. Choices are: created_by, created_date, departments, departments_id, email, groups, id, is_active, is_approved, is_superuser, last_login, logentry, modified_by, modified_date, password, role, role_id, user_permissions, userloginlog, username
[2021-05-31 10:30:00] ERROR Error in Creating New User
Traceback (most recent call last):
  File "D:\Adventbiz\FinanceControlledApplication\BusinessModules\ModuleDetails\views.py", line 255, in create_user_temp
    details = Users.objects.filter(user_name=user_name, id=user_id)
  File "C:\Users\user\Envs\django\lib\site-packages\django\db\models\manager.py", line 85, in manager_method
    return getattr(self.get_queryset(), name)(*args, **kwargs)
  File "C:\Users\user\Envs\django\lib\site-packages\django\db\models\query.py", line 941, in filter
    return self._filter_or_exclude(False, args, kwargs)
  File "C:\Users\user\Envs\django\lib\site-packages\django\db\models\query.py", line 961, in _filter_or_exclude
    clone._filter_or_exclude_inplace(negate, args, kwargs)
  File "C:\Users\user\Envs\django\lib\site-packages\django\db\models\query.py", line 968, in _filter_or_exclude_inplace
    self._query.add_q(Q(*args, **kwargs))
  File "C:\Users\user\Envs\django\lib\site-packages\django\db\models\sql\query.py", line 1396, in add_q
    clause, _ = self._add_q(q_object, self.used_aliases)
  File "C:\Users\user\Envs\django\lib\site-packages\django\db\models\sql\query.py", line 1415, in _add_q
    child_clause, needed_inner = self.build_filter(
  File "C:\Users\user\Envs\django\lib\site-packages\django\db\models\sql\query.py", line 1289, in build_filter
    lookups, parts, reffed_expression = self.solve_lookup_type(arg)
  File "C:\Users\user\Envs\django\lib\site-packages\django\db\models\sql\query.py", line 1115, in solve_lookup_type
    _, field, _, lookup_parts = self.names_to_path(lookup_splitted, self.get_meta())
  File "C:\Users\user\Envs\django\lib\site-packages\django\db\models\sql\query.py", line 1542, in names_to_path
    raise FieldError("Cannot resolve keyword '%s' into field. "
django.core.exceptions.FieldError: Cannot resolve keyword 'user_name' into field. Choices are: created_by, created_date, departments, departments_id, email, groups, id, is_active, is_approved, is_superuser, last_login, logentry, modified_by, modified_date, password, role, role_id, user_permissions, userloginlog, username
[2021-05-31 10:31:57] INFO Create PRF Email send to the Department Head
[2021-05-31 10:41:10] INFO Create PRF Email send to the Department Head
[2021-05-31 10:41:42] ERROR local variable 'user_name' referenced before assignment
[2021-05-31 10:41:42] ERROR Error in Creating New User
Traceback (most recent call last):
  File "D:\Adventbiz\FinanceControlledApplication\BusinessModules\ModuleDetails\views.py", line 255, in create_user_temp
    if len(str(user_name)) > 0:
UnboundLocalError: local variable 'user_name' referenced before assignment
[2021-05-31 10:43:32] INFO Create PRF Email send to the Department Head
